[INFO     2013-10-26 13:22:39,350 bulkloader.py] Logging to bulkloader-log-20131026.132239
[INFO     2013-10-26 13:22:39,350 bulkloader.py] Throttling transfers:
[INFO     2013-10-26 13:22:39,350 bulkloader.py] Bandwidth: 250000 bytes/second
[INFO     2013-10-26 13:22:39,350 bulkloader.py] HTTP connections: 8/second
[INFO     2013-10-26 13:22:39,350 bulkloader.py] Entities inserted/fetched/modified: 20/second
[INFO     2013-10-26 13:22:39,350 bulkloader.py] Batch Size: 500
[INFO     2013-10-26 13:22:43,690 bulkloader.py] Opening database: bulkloader-progress-20131026.132239.sql3
[DEBUG    2013-10-26 13:22:44,153 adaptive_thread_pool.py] [WorkerThread-0] WorkerThread: started
[DEBUG    2013-10-26 13:22:44,153 adaptive_thread_pool.py] [WorkerThread-1] WorkerThread: started
[DEBUG    2013-10-26 13:22:44,154 adaptive_thread_pool.py] [WorkerThread-2] WorkerThread: started
[DEBUG    2013-10-26 13:22:44,154 adaptive_thread_pool.py] [WorkerThread-3] WorkerThread: started
[DEBUG    2013-10-26 13:22:44,155 adaptive_thread_pool.py] [WorkerThread-4] WorkerThread: started
[DEBUG    2013-10-26 13:22:44,155 adaptive_thread_pool.py] [WorkerThread-5] WorkerThread: started
[DEBUG    2013-10-26 13:22:44,156 adaptive_thread_pool.py] [WorkerThread-6] WorkerThread: started
[DEBUG    2013-10-26 13:22:44,156 adaptive_thread_pool.py] [WorkerThread-7] WorkerThread: started
[DEBUG    2013-10-26 13:22:44,156 adaptive_thread_pool.py] [WorkerThread-8] WorkerThread: started
[DEBUG    2013-10-26 13:22:44,157 adaptive_thread_pool.py] [WorkerThread-9] WorkerThread: started
[DEBUG    2013-10-26 13:22:44,157 bulkloader.py] Configuring remote_api. url_path = /_ah/remote_api, servername = localhost:8080
[DEBUG    2013-10-26 13:22:44,157 bulkloader.py] Bulkloader using app_id: dev~s~measureheaven
[INFO     2013-10-26 13:22:44,157 bulkloader.py] Connecting to localhost:8080/_ah/remote_api
[DEBUG    2013-10-26 13:22:44,182 bulkloader.py] [Thread-11] ProgressTrackerThread: started
[DEBUG    2013-10-26 13:22:44,182 bulkloader.py] [Thread-12] DataSourceThread: started
[INFO     2013-10-26 13:22:44,183 bulkloader.py] Starting import; maximum 500 entities per post
[DEBUG    2013-10-26 13:22:44,190 bulkloader.py] [Thread-12] DataSourceThread: exiting
[DEBUG    2013-10-26 13:22:44,190 bulkloader.py] Waiting for worker threads to finish...
[DEBUG    2013-10-26 13:22:44,218 adaptive_thread_pool.py] [WorkerThread-0] Got work item [1-500]
[ERROR    2013-10-26 13:22:44,228 adaptive_thread_pool.py] [WorkerThread-0] WorkerThread:
Traceback (most recent call last):
  File "/home/diegob/Google/google_appengine/google/appengine/tools/adaptive_thread_pool.py", line 175, in WorkOnItems
    status, instruction = item.PerformWork(self.__thread_pool)
  File "/home/diegob/Google/google_appengine/google/appengine/tools/bulkloader.py", line 756, in PerformWork
    transfer_time = self._TransferItem(thread_pool)
  File "/home/diegob/Google/google_appengine/google/appengine/tools/bulkloader.py", line 925, in _TransferItem
    self.content = self.request_manager.EncodeContent(self.rows)
  File "/home/diegob/Google/google_appengine/google/appengine/tools/bulkloader.py", line 1429, in EncodeContent
    entity = loader.create_entity(values, key_name=key, parent=parent)
  File "/home/diegob/Google/google_appengine/google/appengine/tools/bulkloader.py", line 2777, in create_entity
    entity = model_class(**properties)
  File "/home/diegob/Google/google_appengine/google/appengine/ext/db/__init__.py", line 970, in __init__
    prop.__set__(self, value)
  File "/home/diegob/Google/google_appengine/google/appengine/ext/db/__init__.py", line 614, in __set__
    value = self.validate(value)
  File "/home/diegob/Google/google_appengine/google/appengine/ext/db/__init__.py", line 3014, in validate
    (self.name, self.data_type.__name__, value))
BadValueError: Property time must be a datetime, but was datetime.date(2013, 10, 26)
[DEBUG    2013-10-26 13:22:44,231 adaptive_thread_pool.py] [WorkerThread-0] WorkerThread: exiting
[INFO     2013-10-26 13:22:44,231 adaptive_thread_pool.py] [WorkerThread-1] Backing off due to errors: 1.0 seconds
[INFO     2013-10-26 13:22:44,691 bulkloader.py] An error occurred. Shutting down...
[DEBUG    2013-10-26 13:22:44,691 adaptive_thread_pool.py] [WorkerThread-2] WorkerThread: exiting
[DEBUG    2013-10-26 13:22:44,692 adaptive_thread_pool.py] [WorkerThread-5] WorkerThread: exiting
[DEBUG    2013-10-26 13:22:44,692 adaptive_thread_pool.py] [WorkerThread-7] WorkerThread: exiting
[DEBUG    2013-10-26 13:22:44,692 adaptive_thread_pool.py] [WorkerThread-4] WorkerThread: exiting
[DEBUG    2013-10-26 13:22:44,692 adaptive_thread_pool.py] [WorkerThread-3] WorkerThread: exiting
[DEBUG    2013-10-26 13:22:44,692 adaptive_thread_pool.py] [WorkerThread-8] WorkerThread: exiting
[DEBUG    2013-10-26 13:22:44,693 adaptive_thread_pool.py] [WorkerThread-6] WorkerThread: exiting
[DEBUG    2013-10-26 13:22:44,693 adaptive_thread_pool.py] [WorkerThread-9] WorkerThread: exiting
[DEBUG    2013-10-26 13:22:44,694 adaptive_thread_pool.py] Waiting for Anonymous_WorkerThread to exit
[DEBUG    2013-10-26 13:22:44,694 adaptive_thread_pool.py] Waiting for Anonymous_WorkerThread to exit
[DEBUG    2013-10-26 13:22:44,732 adaptive_thread_pool.py] [WorkerThread-1] WorkerThread: exiting
[DEBUG    2013-10-26 13:22:44,732 adaptive_thread_pool.py] Waiting for Anonymous_WorkerThread to exit
[DEBUG    2013-10-26 13:22:44,732 adaptive_thread_pool.py] Waiting for Anonymous_WorkerThread to exit
[DEBUG    2013-10-26 13:22:44,732 adaptive_thread_pool.py] Waiting for Anonymous_WorkerThread to exit
[DEBUG    2013-10-26 13:22:44,732 adaptive_thread_pool.py] Waiting for Anonymous_WorkerThread to exit
[DEBUG    2013-10-26 13:22:44,732 adaptive_thread_pool.py] Waiting for Anonymous_WorkerThread to exit
[DEBUG    2013-10-26 13:22:44,732 adaptive_thread_pool.py] Waiting for Anonymous_WorkerThread to exit
[DEBUG    2013-10-26 13:22:44,732 adaptive_thread_pool.py] Waiting for Anonymous_WorkerThread to exit
[DEBUG    2013-10-26 13:22:44,733 adaptive_thread_pool.py] Waiting for Anonymous_WorkerThread to exit
[ERROR    2013-10-26 13:22:44,733 adaptive_thread_pool.py] Error in WorkerThread-0: Property time must be a datetime, but was datetime.date(2013, 10, 26)
[DEBUG    2013-10-26 13:22:44,733 adaptive_thread_pool.py] Traceback (most recent call last):
  File "/home/diegob/Google/google_appengine/google/appengine/tools/adaptive_thread_pool.py", line 175, in WorkOnItems
    status, instruction = item.PerformWork(self.__thread_pool)
  File "/home/diegob/Google/google_appengine/google/appengine/tools/bulkloader.py", line 756, in PerformWork
    transfer_time = self._TransferItem(thread_pool)
  File "/home/diegob/Google/google_appengine/google/appengine/tools/bulkloader.py", line 925, in _TransferItem
    self.content = self.request_manager.EncodeContent(self.rows)
  File "/home/diegob/Google/google_appengine/google/appengine/tools/bulkloader.py", line 1429, in EncodeContent
    entity = loader.create_entity(values, key_name=key, parent=parent)
  File "/home/diegob/Google/google_appengine/google/appengine/tools/bulkloader.py", line 2777, in create_entity
    entity = model_class(**properties)
  File "/home/diegob/Google/google_appengine/google/appengine/ext/db/__init__.py", line 970, in __init__
    prop.__set__(self, value)
  File "/home/diegob/Google/google_appengine/google/appengine/ext/db/__init__.py", line 614, in __set__
    value = self.validate(value)
  File "/home/diegob/Google/google_appengine/google/appengine/ext/db/__init__.py", line 3014, in validate
    (self.name, self.data_type.__name__, value))
BadValueError: Property time must be a datetime, but was datetime.date(2013, 10, 26)

[DEBUG    2013-10-26 13:22:44,733 bulkloader.py] Waiting for progress_thread to terminate...
[DEBUG    2013-10-26 13:22:44,809 bulkloader.py] [Thread-11] ProgressTrackerThread: exiting
[DEBUG    2013-10-26 13:22:44,847 bulkloader.py] ... done.
[INFO     2013-10-26 13:22:44,848 bulkloader.py] 1000 entities total, 0 previously transferred
[INFO     2013-10-26 13:22:44,848 bulkloader.py] 0 entities (937 bytes) transferred in 5.5 seconds
[INFO     2013-10-26 13:22:44,848 bulkloader.py] Some entities not successfully transferred
